TESTS WITH ERRORS 
test13 (gradingtests.UnitTests)
Traceback (most recent call last):
  File "/Users/k2i/academics/automatedgradingapp/app/testing/kb-inference/gradingtests.py", line 373, in test13
    self.assertTrue(str(answer1[0]).startswith("No bindings"))
IndexError: list index out of range

test14 (gradingtests.UnitTests)
Traceback (most recent call last):
  File "/Users/k2i/academics/automatedgradingapp/app/testing/kb-inference/gradingtests.py", line 405, in test14
    KB.kb_retract(fact2)
  File "/Users/k2i/academics/automatedgradingapp/app/testing/kb-inference/student_code.py", line 151, in kb_retract
    self.kb_retract_helper(fact_or_rule)
  File "/Users/k2i/academics/automatedgradingapp/app/testing/kb-inference/student_code.py", line 180, in kb_retract_helper
    ind3 = f.supported_by.index(f_r)
ValueError: Fact('fact', Statement('healthGoesTo', [Term(Constant('A'))]), True, [], [Fact('fact', Statement('heathyPerson', [Term(Constant('A'))]), False, [], [], [])], []) is not in list

-------------------------------
TESTS FAILED  
test10 (gradingtests.UnitTests)
Traceback (most recent call last):
  File "/Users/k2i/academics/automatedgradingapp/app/testing/kb-inference/gradingtests.py", line 282, in test10
    self.assertFalse(answer2)
AssertionError: True is not false

test4 (gradingtests.UnitTests)
Traceback (most recent call last):
  File "/Users/k2i/academics/automatedgradingapp/app/testing/kb-inference/gradingtests.py", line 98, in test4
    self.assertFalse(answer6)
AssertionError: True is not false

test5 (gradingtests.UnitTests)
Traceback (most recent call last):
  File "/Users/k2i/academics/automatedgradingapp/app/testing/kb-inference/gradingtests.py", line 148, in test5
    self.assertFalse(answer3)
AssertionError: True is not false

-------------------------------
TESTS SKIPPED 
-------------------------------
